Workbook
Name Amort_TotalInterest: Amortization_Schedule!$I$5
Name Amort_TotalPayments: Amortization_Schedule!$I$3
Name Amort_TotalPrincipal: Amortization_Schedule!$I$4
Name Assump_BaseRate: Assumptions!$B$9
Name Assump_Budget: Assumptions!$B$10
Name Assump_ClosingCosts: Assumptions!$B$18
Name Assump_CurrRate: Assumptions!$B$15
Name Assump_DPPct: Assumptions!$B$5
Name Assump_HoldPeriod: Assumptions!$B$19
Name Assump_HomePrice: Assumptions!$B$4
Name Assump_LoanAmt: Assumptions!$B$6
Name Assump_PropRate: Assumptions!$B$16
Name Assump_RemBal: Assumptions!$B$14
Name Assump_RemTerm: Assumptions!$B$17
Name Assump_TermMos: Assumptions!$B$8
Name Assump_TermYrs: Assumptions!$B$7
Name LatestRate: Rate_Data!$H$2
Name Refi_BreakEvenMos: Refinance_Analysis!$B$16
Name Refi_CurrPayment: Refinance_Analysis!$B$13
Name Refi_DecisionFlag: Refinance_Analysis!$A$22
Name Refi_MonthlySavings: Refinance_Analysis!$B$15
Name Refi_NewPayment: Refinance_Analysis!$B$14
Name RSM_Affordable: Rate_Shock_Model!$H$11:$H$16
Name RSM_BaseAffordable: Rate_Shock_Model!$H$13
Name RSM_BasePayment: Rate_Shock_Model!$D$13
Name RSM_BaseTotalInterest: Rate_Shock_Model!$F$13
Name RSM_Labels: Rate_Shock_Model!$A$11:$A$16
Name RSM_Payments: Rate_Shock_Model!$D$11:$D$16
Name RSM_TotalInterest: Rate_Shock_Model!$F$11:$F$16

Sheet Project_Map
A1: Rate Shock Loan Affordability & Refinance Dashboard
F2: =IF(OR(ISERROR(Rate_Shock_Model!D13),ISERROR(Rate_Shock_Model!F13),ISERROR(Refinance_Analysis!B16),ISERROR(Amortization_Schedule!I5),Amortization_Schedule!I6<>"✓ PASS",Amortization_Schedule!I8<>"✓ PASS"),"⚠ Issues Detected — Check Model Sheets","✓ All Key Cells OK") -> ✓ All Key Cells OK
A3: Primary Tool: | B3: Microsoft Excel
A4: Primary Dataset: | B4: FRED / Freddie Mac 30-Year Fixed Mortgage Rate Series (MORTGAGE30US)
A6: Project Objective
A7: This workbook analyzes how changes in mortgage interest rates affect borrower affordability, monthly payments, lifetime interest burden, and refinance decisions. Using historical U.S. 30-year fixed mortgage rate data (FRED/Freddie Mac, 1971-2026), the model converts macro-rate conditions into practical household finance scenarios and decision-support outputs.
A9: Business Questions
A10: ID | B10: Business Question | C10: Why It Matters | D10: Primary Answer Location
A11: BQ1 | B11: How have 30-year fixed mortgage rates changed historically, and where does the latest rate sit relative to the past? | C11: Establishes the rate environment that drives the model | D11: Rate_Data; Dashboard
A12: BQ2 | B12: How much does a mortgage rate increase or decrease change the monthly payment on a representative loan? | C12: Measures payment sensitivity to rate shocks | D12: Rate_Shock_Model; Dashboard
A13: BQ3 | B13: How does the interest-rate environment affect total interest paid over the full life of the loan? | C13: Shows the long-term cost of rate changes | D13: Rate_Shock_Model; Amortization_Schedule; Dashboard
A14: BQ4 | B14: Given a fixed monthly payment budget, how much loan principal is affordable at different mortgage rates? | C14: Quantifies purchasing-power erosion when rates rise | D14: Rate_Shock_Model; Dashboard
A15: BQ5 | B15: Under what conditions does refinancing become financially attractive, and how long does it take to break even? | C15: Supports a practical refinance decision | D15: Refinance_Analysis; Dashboard
A17: Workbook Navigation Map
A18: Worksheet | B18: Role in the Model | C18: Key Outputs | D18: BQ Answered
A19: Project_Map | B19: Executive overview & navigation | C19: Objective, BQ list, sheet map, scope, portfolio framing | D19: —
A20: Rate_Data | B20: Historical rate data & statistics | C20: Latest rate, min/max/avg, helper columns, summary stats | D20: BQ1
A21: Assumptions | B21: Central input & scenario-control panel | C21: Loan inputs, refinance inputs, named ranges | D21: All
A22: Rate_Shock_Model | B22: Interest-rate scenario analysis | C22: 6-scenario payment, interest, cost, affordability table | D22: BQ2-BQ4
A23: Amortization_Schedule | B23: Base-case loan mechanics over time | C23: 360-row P&I schedule, balance decline, totals | D23: BQ2-BQ3
A24: Refinance_Analysis | B24: Refinance comparison & break-even model | C24: Monthly savings, break-even months, decision flag | D24: BQ5
A25: Dashboard | B25: Executive visual summary | C25: 5 KPI cards, 4 charts, refinance summary | D25: All
A27: Core Formula Families
A28: Formula / Logic | B28: Project Use
A29: PMT | B29: Monthly mortgage payment under each rate scenario and base case
A30: PV | B30: Affordable loan principal at a fixed target monthly payment
A31: CUMIPMT | B31: Total interest paid over the full loan term by scenario
A32: PPMT / IPMT | B32: Principal and interest components by period in amortization
A33: IF | B33: Decision flags, refinance break-even interpretation, error guards
A34: IFERROR | B34: Graceful handling of division-by-zero and invalid inputs
A35: INDEX / MATCH | B35: Latest-rate retrieval from Rate_Data; robust to data appends
A36: TEXT / YEAR | B36: Date helper columns and formatted display labels
A37: Scope — Version 1
A38: INCLUDED IN VERSION 1 | D38: EXCLUDED FROM VERSION 1
A39: • Historical 30-year fixed rate analysis (FRED, 1971-2026) | D39: • Property taxes, insurance, PMI, HOA fees
A40: • Six-scenario rate shock analysis (-1.00% to +1.50%) | D40: • Adjustable-rate mortgage (ARM) modeling
A41: • Full 360-payment base-case amortization schedule | D41: • Credit-score-based loan pricing
A42: • Refinance break-even analysis with decision flag | D42: • Regional housing-price differences
A43: • Executive dashboard with 5 KPI cards and 4 charts | D43: • VBA macros or automated data refresh
D44: • AWS pipeline (planned for a later phase)
...

Sheet Rate_Data
A1: observation_date | B1: MORTGAGE30US | C1: Rate_Decimal | D1: Year | E1: Month_Year | F1: CurrentRateLine | G1: Rate Summary Statistics
A2: 26025 | B2: 7.33 | C2: =B2/100 -> 0.0733 | D2: =YEAR(A2) -> 1971 | E2: =TEXT(A2,"MMM-YYYY") -> Apr-1971 | F2: =$H$2 -> 6.36 | G2: Latest Rate | H2: =INDEX(B:B,COUNTA(B:B)) -> 6.36
A3: 26032 | B3: 7.31 | C3: =B3/100 -> 0.0731 | D3: =YEAR(A3) -> 1971 | E3: =TEXT(A3,"MMM-YYYY") -> Apr-1971 | F3: =$H$2 -> 6.36 | G3: Historical Minimum | H3: =MIN(B:B) -> 2.65
A4: 26039 | B4: 7.31 | C4: =B4/100 -> 0.0731 | D4: =YEAR(A4) -> 1971 | E4: =TEXT(A4,"MMM-YYYY") -> Apr-1971 | F4: =$H$2 -> 6.36 | G4: Historical Maximum | H4: =MAX(B:B) -> 18.63
A5: 26046 | B5: 7.31 | C5: =B5/100 -> 0.0731 | D5: =YEAR(A5) -> 1971 | E5: =TEXT(A5,"MMM-YYYY") -> Apr-1971 | F5: =$H$2 -> 6.36 | G5: Historical Average | H5: =AVERAGE(B:B) -> 7.687633
A6: 26053 | B6: 7.29 | C6: =B6/100 -> 0.0729 | D6: =YEAR(A6) -> 1971 | E6: =TEXT(A6,"MMM-YYYY") -> Apr-1971 | F6: =$H$2 -> 6.36 | G6: 52-Week Trailing Avg | H6: =AVERAGE(B2827:B2878) -> 6.3701923
A7: 26060 | B7: 7.38 | C7: =B7/100 -> 0.0738 | D7: =YEAR(A7) -> 1971 | E7: =TEXT(A7,"MMM-YYYY") -> May-1971 | F7: =$H$2 -> 6.36 | G7: Data Start | H7: =TEXT(INDEX(A:A,2),"mmm d, yyyy") -> Apr 2, 1971
A8: 26067 | B8: 7.42 | C8: =B8/100 -> 0.0742 | D8: =YEAR(A8) -> 1971 | E8: =TEXT(A8,"MMM-YYYY") -> May-1971 | F8: =$H$2 -> 6.36 | G8: Data End | H8: =TEXT(INDEX(A:A,COUNTA(B:B)),"mmm d, yyyy") -> May 14, 2026
A9: 26074 | B9: 7.44 | C9: =B9/100 -> 0.0744 | D9: =YEAR(A9) -> 1971 | E9: =TEXT(A9,"MMM-YYYY") -> May-1971 | F9: =$H$2 -> 6.36
A10: 26081 | B10: 7.46 | C10: =B10/100 -> 0.0746 | D10: =YEAR(A10) -> 1971 | E10: =TEXT(A10,"MMM-YYYY") -> May-1971 | F10: =$H$2 -> 6.36
A11: 26088 | B11: 7.52 | C11: =B11/100 -> 0.0752 | D11: =YEAR(A11) -> 1971 | E11: =TEXT(A11,"MMM-YYYY") -> Jun-1971 | F11: =$H$2 -> 6.36
A12: 26095 | B12: 7.52 | C12: =B12/100 -> 0.0752 | D12: =YEAR(A12) -> 1971 | E12: =TEXT(A12,"MMM-YYYY") -> Jun-1971 | F12: =$H$2 -> 6.36
A13: 26102 | B13: 7.54 | C13: =B13/100 -> 0.0754 | D13: =YEAR(A13) -> 1971 | E13: =TEXT(A13,"MMM-YYYY") -> Jun-1971 | F13: =$H$2 -> 6.36
A14: 26109 | B14: 7.54 | C14: =B14/100 -> 0.0754 | D14: =YEAR(A14) -> 1971 | E14: =TEXT(A14,"MMM-YYYY") -> Jun-1971 | F14: =$H$2 -> 6.36
A15: 26116 | B15: 7.54 | C15: =B15/100 -> 0.0754 | D15: =YEAR(A15) -> 1971 | E15: =TEXT(A15,"MMM-YYYY") -> Jul-1971 | F15: =$H$2 -> 6.36
A16: 26123 | B16: 7.54 | C16: =B16/100 -> 0.0754 | D16: =YEAR(A16) -> 1971 | E16: =TEXT(A16,"MMM-YYYY") -> Jul-1971 | F16: =$H$2 -> 6.36
A17: 26130 | B17: 7.6 | C17: =B17/100 -> 0.076 | D17: =YEAR(A17) -> 1971 | E17: =TEXT(A17,"MMM-YYYY") -> Jul-1971 | F17: =$H$2 -> 6.36
A18: 26137 | B18: 7.65 | C18: =B18/100 -> 0.0765 | D18: =YEAR(A18) -> 1971 | E18: =TEXT(A18,"MMM-YYYY") -> Jul-1971 | F18: =$H$2 -> 6.36
A19: 26144 | B19: 7.69 | C19: =B19/100 -> 0.0769 | D19: =YEAR(A19) -> 1971 | E19: =TEXT(A19,"MMM-YYYY") -> Jul-1971 | F19: =$H$2 -> 6.36
A20: 26151 | B20: 7.66 | C20: =B20/100 -> 0.0766 | D20: =YEAR(A20) -> 1971 | E20: =TEXT(A20,"MMM-YYYY") -> Aug-1971 | F20: =$H$2 -> 6.36
... A2878: 46156 | B2878: 6.36 | C2878: =B2878/100 -> 0.0636 | D2878: =YEAR(A2878) -> 2026 | E2878: =TEXT(A2878,"MMM-YYYY") -> May-2026 | F2878: =$H$2 -> 6.36

Sheet Assumptions
A1: Assumptions — Input Control Panel
A3: LOAN INPUTS
A4: Home Price | B4: 500000 | D4: Enter purchase price
A5: Down Payment % | B5: 0.2 | D5: Enter as decimal (e.g., 0.20)
A6: Loan Amount | B6: =B4*(1-B5) -> 400000 | D6: Computed: Home Price x (1 - DP%)
A7: Loan Term (years) | B7: =30 -> 30 | D7: Fixed: 30-yr fixed rate model
A8: Loan Term (months) | B8: =B7*12 -> 360 | D8: Computed: 360 months
A9: Base Mortgage Rate | B9: =LatestRate/100 -> 0.0636 | D9: Auto-linked from Rate_Data
A10: Target Monthly Budget | B10: 2500 | D10: Max monthly P&I payment
A13: REFINANCE INPUTS
A14: Remaining Balance | B14: 380000 | D14: Current outstanding principal
A15: Current Mortgage Rate | B15: 0.07 | D15: Enter as decimal (e.g., 0.07)
A16: Proposed Refinance Rate | B16: 0.06 | D16: Enter as decimal (e.g., 0.06)
A17: Remaining Term (months) | B17: 324 | D17: Months left on current loan
A18: Closing Costs | B18: 6000 | D18: Total refi closing costs
A19: Expected Holding Period | B19: 60 | D19: Months you plan to stay

Sheet Rate_Shock_Model
A1: Rate Shock Scenario Analysis
A2: Key Inputs (from Assumptions)
A3: Loan Amount | B3: =Assump_LoanAmt -> 400000
A4: Base Rate | B4: =Assump_BaseRate -> 0.0636
A5: Loan Term (months) | B5: =Assump_TermMos -> 360
A6: Monthly Budget | B6: =Assump_Budget -> 2500
A10: Scenario | B10: Rate Offset | C10: Scenario Rate | D10: Monthly Payment | E10: Δ Payment vs. Base | F10: Total Lifetime Interest | G10: Total Loan Cost | H10: Affordable Principal
A11: Rate −1.00% | B11: -0.01 | C11: =Assump_BaseRate+B11 -> 0.0536 | D11: =IFERROR(PMT(C11/12,Assump_TermMos,-Assump_LoanAmt),"—") -> 2236.1459 | E11: =IFERROR(D11-$D$13,"—") -> -255.41077 | F11: =IFERROR(-CUMIPMT(C11/12,Assump_TermMos,Assump_LoanAmt,1,Assump_TermMos,0),"—") -> 405012.52 | G11: =IFERROR(Assump_LoanAmt+F11,"—") -> 805012.52 | H11: =IFERROR(-PV(C11/12,Assump_TermMos,Assump_Budget),"—") -> 447198.01
A12: Rate −0.50% | B12: -0.005 | C12: =Assump_BaseRate+B12 -> 0.0586 | D12: =IFERROR(PMT(C12/12,Assump_TermMos,-Assump_LoanAmt),"—") -> 2362.3177 | E12: =IFERROR(D12-$D$13,"—") -> -129.23891 | F12: =IFERROR(-CUMIPMT(C12/12,Assump_TermMos,Assump_LoanAmt,1,Assump_TermMos,0),"—") -> 450434.39 | G12: =IFERROR(Assump_LoanAmt+F12,"—") -> 850434.39 | H12: =IFERROR(-PV(C12/12,Assump_TermMos,Assump_Budget),"—") -> 423313.08
A13: Base Case | B13: 0 | C13: =Assump_BaseRate+B13 -> 0.0636 | D13: =IFERROR(PMT(C13/12,Assump_TermMos,-Assump_LoanAmt),"—") -> 2491.5567 | E13: =0 -> 0 | F13: =IFERROR(-CUMIPMT(C13/12,Assump_TermMos,Assump_LoanAmt,1,Assump_TermMos,0),"—") -> 496960.4 | G13: =IFERROR(Assump_LoanAmt+F13,"—") -> 896960.4 | H13: =IFERROR(-PV(C13/12,Assump_TermMos,Assump_Budget),"—") -> 401355.51
A14: Rate +0.50% | B14: 0.005 | C14: =Assump_BaseRate+B14 -> 0.0686 | D14: =IFERROR(PMT(C14/12,Assump_TermMos,-Assump_LoanAmt),"—") -> 2623.7074 | E14: =IFERROR(D14-$D$13,"—") -> 132.15073 | F14: =IFERROR(-CUMIPMT(C14/12,Assump_TermMos,Assump_LoanAmt,1,Assump_TermMos,0),"—") -> 544534.66 | G14: =IFERROR(Assump_LoanAmt+F14,"—") -> 944534.66 | H14: =IFERROR(-PV(C14/12,Assump_TermMos,Assump_Budget),"—") -> 381140.06
A15: Rate +1.00% | B15: 0.01 | C15: =Assump_BaseRate+B15 -> 0.0736 | D15: =IFERROR(PMT(C15/12,Assump_TermMos,-Assump_LoanAmt),"—") -> 2758.6125 | E15: =IFERROR(D15-$D$13,"—") -> 267.05588 | F15: =IFERROR(-CUMIPMT(C15/12,Assump_TermMos,Assump_LoanAmt,1,Assump_TermMos,0),"—") -> 593100.51 | G15: =IFERROR(Assump_LoanAmt+F15,"—") -> 993100.51 | H15: =IFERROR(-PV(C15/12,Assump_TermMos,Assump_Budget),"—") -> 362501.07
A16: Rate +1.50% | B16: 0.015 | C16: =Assump_BaseRate+B16 -> 0.0786 | D16: =IFERROR(PMT(C16/12,Assump_TermMos,-Assump_LoanAmt),"—") -> 2896.1141 | E16: =IFERROR(D16-$D$13,"—") -> 404.5574 | F16: =IFERROR(-CUMIPMT(C16/12,Assump_TermMos,Assump_LoanAmt,1,Assump_TermMos,0),"—") -> 642601.06 | G16: =IFERROR(Assump_LoanAmt+F16,"—") -> 1042601.1 | H16: =IFERROR(-PV(C16/12,Assump_TermMos,Assump_Budget),"—") -> 345290.27

Sheet Amortization_Schedule
A1: Base-Case Loan Amortization Schedule
A2: Loan Parameters | H2: Schedule Totals
A3: Loan Amount | B3: =Assump_LoanAmt -> 400000 | H3: Total Payments | I3: =SUM(C10:C369) -> 896960.4
A4: Annual Rate | B4: =Assump_BaseRate -> 0.0636 | H4: Total Principal Paid | I4: =SUM(D10:D369) -> 400000
A5: Monthly Rate | B5: =Assump_BaseRate/12 -> 0.0053 | H5: Total Interest Paid | I5: =SUM(E10:E369) -> 496960.4
A6: Term (months) | B6: =Assump_TermMos -> 360 | H6: Principal = Loan Amt? | I6: =IF(ABS(I4-Assump_LoanAmt)<1,"✓ PASS","✗ FAIL") -> ✓ PASS
H7: Ending Balance (Mo 360) | I7: =F369 -> 2.3646862e-11
H8: Balance ≈ $0? | I8: =IF(ABS(F369)<1,"✓ PASS","✗ FAIL") -> ✓ PASS
A9: Payment # | B9: Beginning Balance | C9: Monthly Payment | D9: Principal Paid | E9: Interest Paid | F9: Ending Balance
A10: =1 -> 1 | B10: =Assump_LoanAmt -> 400000 | C10: =IFERROR(PMT(Assump_BaseRate/12,Assump_TermMos,-Assump_LoanAmt),0) -> 2491.5567 | D10: =IFERROR(PPMT(Assump_BaseRate/12,A10,Assump_TermMos,-Assump_LoanAmt),0) -> 371.55666 | E10: =IFERROR(IPMT(Assump_BaseRate/12,A10,Assump_TermMos,-Assump_LoanAmt),0) -> 2120 | F10: =IFERROR(B10-D10,0) -> 399628.44
A11: =A10+1 -> 2 | B11: =F10 -> 399628.44 | C11: =IFERROR(PMT(Assump_BaseRate/12,Assump_TermMos,-Assump_LoanAmt),0) -> 2491.5567 | D11: =IFERROR(PPMT(Assump_BaseRate/12,A11,Assump_TermMos,-Assump_LoanAmt),0) -> 373.52591 | E11: =IFERROR(IPMT(Assump_BaseRate/12,A11,Assump_TermMos,-Assump_LoanAmt),0) -> 2118.0307 | F11: =IFERROR(B11-D11,0) -> 399254.92
A12: =A11+1 -> 3 | B12: =F11 -> 399254.92 | C12: =IFERROR(PMT(Assump_BaseRate/12,Assump_TermMos,-Assump_LoanAmt),0) -> 2491.5567 | D12: =IFERROR(PPMT(Assump_BaseRate/12,A12,Assump_TermMos,-Assump_LoanAmt),0) -> 375.5056 | E12: =IFERROR(IPMT(Assump_BaseRate/12,A12,Assump_TermMos,-Assump_LoanAmt),0) -> 2116.0511 | F12: =IFERROR(B12-D12,0) -> 398879.41
A13: =A12+1 -> 4 | B13: =F12 -> 398879.41 | C13: =IFERROR(PMT(Assump_BaseRate/12,Assump_TermMos,-Assump_LoanAmt),0) -> 2491.5567 | D13: =IFERROR(PPMT(Assump_BaseRate/12,A13,Assump_TermMos,-Assump_LoanAmt),0) -> 377.49578 | E13: =IFERROR(IPMT(Assump_BaseRate/12,A13,Assump_TermMos,-Assump_LoanAmt),0) -> 2114.0609 | F13: =IFERROR(B13-D13,0) -> 398501.92
A14: =A13+1 -> 5 | B14: =F13 -> 398501.92 | C14: =IFERROR(PMT(Assump_BaseRate/12,Assump_TermMos,-Assump_LoanAmt),0) -> 2491.5567 | D14: =IFERROR(PPMT(Assump_BaseRate/12,A14,Assump_TermMos,-Assump_LoanAmt),0) -> 379.4965 | E14: =IFERROR(IPMT(Assump_BaseRate/12,A14,Assump_TermMos,-Assump_LoanAmt),0) -> 2112.0602 | F14: =IFERROR(B14-D14,0) -> 398122.42
A15: =A14+1 -> 6 | B15: =F14 -> 398122.42 | C15: =IFERROR(PMT(Assump_BaseRate/12,Assump_TermMos,-Assump_LoanAmt),0) -> 2491.5567 | D15: =IFERROR(PPMT(Assump_BaseRate/12,A15,Assump_TermMos,-Assump_LoanAmt),0) -> 381.50783 | E15: =IFERROR(IPMT(Assump_BaseRate/12,A15,Assump_TermMos,-Assump_LoanAmt),0) -> 2110.0488 | F15: =IFERROR(B15-D15,0) -> 397740.91
A16: =A15+1 -> 7 | B16: =F15 -> 397740.91 | C16: =IFERROR(PMT(Assump_BaseRate/12,Assump_TermMos,-Assump_LoanAmt),0) -> 2491.5567 | D16: =IFERROR(PPMT(Assump_BaseRate/12,A16,Assump_TermMos,-Assump_LoanAmt),0) -> 383.52983 | E16: =IFERROR(IPMT(Assump_BaseRate/12,A16,Assump_TermMos,-Assump_LoanAmt),0) -> 2108.0268 | F16: =IFERROR(B16-D16,0) -> 397357.38
A17: =A16+1 -> 8 | B17: =F16 -> 397357.38 | C17: =IFERROR(PMT(Assump_BaseRate/12,Assump_TermMos,-Assump_LoanAmt),0) -> 2491.5567 | D17: =IFERROR(PPMT(Assump_BaseRate/12,A17,Assump_TermMos,-Assump_LoanAmt),0) -> 385.56253 | E17: =IFERROR(IPMT(Assump_BaseRate/12,A17,Assump_TermMos,-Assump_LoanAmt),0) -> 2105.9941 | F17: =IFERROR(B17-D17,0) -> 396971.82
A18: =A17+1 -> 9 | B18: =F17 -> 396971.82 | C18: =IFERROR(PMT(Assump_BaseRate/12,Assump_TermMos,-Assump_LoanAmt),0) -> 2491.5567 | D18: =IFERROR(PPMT(Assump_BaseRate/12,A18,Assump_TermMos,-Assump_LoanAmt),0) -> 387.60602 | E18: =IFERROR(IPMT(Assump_BaseRate/12,A18,Assump_TermMos,-Assump_LoanAmt),0) -> 2103.9506 | F18: =IFERROR(B18-D18,0) -> 396584.21
A19: =A18+1 -> 10 | B19: =F18 -> 396584.21 | C19: =IFERROR(PMT(Assump_BaseRate/12,Assump_TermMos,-Assump_LoanAmt),0) -> 2491.5567 | D19: =IFERROR(PPMT(Assump_BaseRate/12,A19,Assump_TermMos,-Assump_LoanAmt),0) -> 389.66033 | E19: =IFERROR(IPMT(Assump_BaseRate/12,A19,Assump_TermMos,-Assump_LoanAmt),0) -> 2101.8963 | F19: =IFERROR(B19-D19,0) -> 396194.55
A20: =A19+1 -> 11 | B20: =F19 -> 396194.55 | C20: =IFERROR(PMT(Assump_BaseRate/12,Assump_TermMos,-Assump_LoanAmt),0) -> 2491.5567 | D20: =IFERROR(PPMT(Assump_BaseRate/12,A20,Assump_TermMos,-Assump_LoanAmt),0) -> 391.72553 | E20: =IFERROR(IPMT(Assump_BaseRate/12,A20,Assump_TermMos,-Assump_LoanAmt),0) -> 2099.8311 | F20: =IFERROR(B20-D20,0) -> 395802.83
A21: =A20+1 -> 12 | B21: =F20 -> 395802.83 | C21: =IFERROR(PMT(Assump_BaseRate/12,Assump_TermMos,-Assump_LoanAmt),0) -> 2491.5567 | D21: =IFERROR(PPMT(Assump_BaseRate/12,A21,Assump_TermMos,-Assump_LoanAmt),0) -> 393.80167 | E21: =IFERROR(IPMT(Assump_BaseRate/12,A21,Assump_TermMos,-Assump_LoanAmt),0) -> 2097.755 | F21: =IFERROR(B21-D21,0) -> 395409.03
A22: =A21+1 -> 13 | B22: =F21 -> 395409.03 | C22: =IFERROR(PMT(Assump_BaseRate/12,Assump_TermMos,-Assump_LoanAmt),0) -> 2491.5567 | D22: =IFERROR(PPMT(Assump_BaseRate/12,A22,Assump_TermMos,-Assump_LoanAmt),0) -> 395.88882 | E22: =IFERROR(IPMT(Assump_BaseRate/12,A22,Assump_TermMos,-Assump_LoanAmt),0) -> 2095.6678 | F22: =IFERROR(B22-D22,0) -> 395013.14
... A369: =A368+1 -> 360 | B369: =F368 -> 2478.421 | C369: =IFERROR(PMT(Assump_BaseRate/12,Assump_TermMos,-Assump_LoanAmt),0) -> 2491.5567 | D369: =IFERROR(PPMT(Assump_BaseRate/12,A369,Assump_TermMos,-Assump_LoanAmt),0) -> 2478.421 | E369: =IFERROR(IPMT(Assump_BaseRate/12,A369,Assump_TermMos,-Assump_LoanAmt),0) -> 13.135631 | F369: =IFERROR(B369-D369,0) -> 2.3646862e-11

Sheet Refinance_Analysis
A1: Refinance Break-Even Analysis
A2: Refinance Inputs (from Assumptions)
A3: Remaining Balance | B3: =Assump_RemBal -> 380000
A4: Current Mortgage Rate | B4: =Assump_CurrRate -> 0.07
A5: Proposed Refinance Rate | B5: =Assump_PropRate -> 0.06
A6: Remaining Term (months) | B6: =Assump_RemTerm -> 324
A7: Closing Costs | B7: =Assump_ClosingCosts -> 6000
A8: Expected Holding Period | B8: =Assump_HoldPeriod -> 60
A12: Refinance Analysis Results
A13: Current Monthly Payment | B13: =IFERROR(PMT(Assump_CurrRate/12,Assump_RemTerm,-Assump_RemBal),"—") -> 2613.6967
A14: New Monthly Payment | B14: =IFERROR(PMT(Assump_PropRate/12,Assump_RemTerm,-Assump_RemBal),"—") -> 2371.1443
A15: Monthly Savings | B15: =IFERROR(B13-B14,"—") -> 242.55239
A16: Break-Even Months | B16: =IFERROR(IF(OR(NOT(ISNUMBER(B15)),B15<=0),"No Savings — Refinance Not Beneficial",Assump_ClosingCosts/B15),"Error") -> 24.736923
A17: Expected Holding Period | B17: =Assump_HoldPeriod -> 60
A18: Total Savings Over Holding Period | B18: =IFERROR(IF(ISNUMBER(B15),B15*Assump_HoldPeriod,"—"),"—") -> 14553.144
A19: Net Benefit After Closing Costs | B19: =IFERROR(IF(ISNUMBER(B18),B18-Assump_ClosingCosts,"—"),"—") -> 8553.1436
A21: Decision
A22: =IF(OR(NOT(ISNUMBER(B15)),B15<=0),"No Savings — Refinance Not Beneficial",IF(ISNUMBER(B16),IF(B16<=Assump_HoldPeriod,"Refinance Makes Sense","Does Not Break Even in Holding Period"),"No Savings — Refinance Not Beneficial")) -> Refinance Makes Sense | B22: =IF(OR(NOT(ISNUMBER(B15)),B15<=0),"No Savings — Refinance Not Beneficial",IF(ISNUMBER(B16),IF(B16<=Assump_HoldPeriod,"Refinance Makes Sense","Does Not Break Even in Holding Period"),"No Savings — Refinance Not Beneficial")) -> Refinance Makes Sense

Sheet Dashboard
A1: Rate Shock Loan Affordability & Refinance Dashboard | Q1: Year | R1: Annual Avg 30-Year Rate | S1: Current Rate Reference | T1: Scenario | U1: Monthly Payment | V1: Total Interest | W1: Affordable Principal | X1: Scenario Rate | Y1: Payment Delta | Z1: Total Loan Cost | AA1: Rate Offset
Q2: 1971 | R2: =SUMIFS(Rate_Data!$B:$B,Rate_Data!$D:$D,Q2)/COUNTIFS(Rate_Data!$D:$D,Q2) -> 7.54175 | S2: =Rate_Data!$H$2 -> 6.36 | T2: =Rate_Shock_Model!A11 -> Rate −1.00% | U2: =Rate_Shock_Model!D11 -> 2236.1459 | V2: =Rate_Shock_Model!F11 -> 405012.52 | W2: =Rate_Shock_Model!H11 -> 447198.01 | X2: =Rate_Shock_Model!C11 -> 0.0536 | Y2: =Rate_Shock_Model!E11 -> -255.41077 | Z2: =Rate_Shock_Model!G11 -> 805012.52 | AA2: =Rate_Shock_Model!B11 -> -0.01
Q3: 1972 | R3: =SUMIFS(Rate_Data!$B:$B,Rate_Data!$D:$D,Q3)/COUNTIFS(Rate_Data!$D:$D,Q3) -> 7.3832692 | S3: =Rate_Data!$H$2 -> 6.36 | T3: =Rate_Shock_Model!A12 -> Rate −0.50% | U3: =Rate_Shock_Model!D12 -> 2362.3177 | V3: =Rate_Shock_Model!F12 -> 450434.39 | W3: =Rate_Shock_Model!H12 -> 423313.08 | X3: =Rate_Shock_Model!C12 -> 0.0586 | Y3: =Rate_Shock_Model!E12 -> -129.23891 | Z3: =Rate_Shock_Model!G12 -> 850434.39 | AA3: =Rate_Shock_Model!B12 -> -0.005
A4: Latest 30-Yr Fixed Rate | D4: Base Case Monthly P&I | G4: Total Lifetime Interest | J4: ="Affordable Loan @ $"&TEXT(Assump_Budget,"#,##0")&"/mo" -> Affordable Loan @ $2,500/mo | M4: Refi Break-Even | Q4: 1973 | R4: =SUMIFS(Rate_Data!$B:$B,Rate_Data!$D:$D,Q4)/COUNTIFS(Rate_Data!$D:$D,Q4) -> 8.0448077 | S4: =Rate_Data!$H$2 -> 6.36 | T4: =Rate_Shock_Model!A13 -> Base Case | U4: =Rate_Shock_Model!D13 -> 2491.5567 | V4: =Rate_Shock_Model!F13 -> 496960.4 | W4: =Rate_Shock_Model!H13 -> 401355.51 | X4: =Rate_Shock_Model!C13 -> 0.0636 | Y4: =Rate_Shock_Model!E13 -> 0 | Z4: =Rate_Shock_Model!G13 -> 896960.4 | AA4: =Rate_Shock_Model!B13 -> 0
A5: =TEXT(Rate_Data!H2,"0.00")&"%" -> 6.36% | D5: =RSM_BasePayment -> 2491.5567 | G5: =RSM_BaseTotalInterest -> 496960.4 | J5: =RSM_BaseAffordable -> 401355.51 | M5: =IF(ISNUMBER(Refi_BreakEvenMos),TEXT(Refi_BreakEvenMos,"0.0")&" months","N/A") -> 24.7 months | Q5: 1974 | R5: =SUMIFS(Rate_Data!$B:$B,Rate_Data!$D:$D,Q5)/COUNTIFS(Rate_Data!$D:$D,Q5) -> 9.1871154 | S5: =Rate_Data!$H$2 -> 6.36 | T5: =Rate_Shock_Model!A14 -> Rate +0.50% | U5: =Rate_Shock_Model!D14 -> 2623.7074 | V5: =Rate_Shock_Model!F14 -> 544534.66 | W5: =Rate_Shock_Model!H14 -> 381140.06 | X5: =Rate_Shock_Model!C14 -> 0.0686 | Y5: =Rate_Shock_Model!E14 -> 132.15073 | Z5: =Rate_Shock_Model!G14 -> 944534.66 | AA5: =Rate_Shock_Model!B14 -> 0.005
Q6: 1975 | R6: =SUMIFS(Rate_Data!$B:$B,Rate_Data!$D:$D,Q6)/COUNTIFS(Rate_Data!$D:$D,Q6) -> 9.0471154 | S6: =Rate_Data!$H$2 -> 6.36 | T6: =Rate_Shock_Model!A15 -> Rate +1.00% | U6: =Rate_Shock_Model!D15 -> 2758.6125 | V6: =Rate_Shock_Model!F15 -> 593100.51 | W6: =Rate_Shock_Model!H15 -> 362501.07 | X6: =Rate_Shock_Model!C15 -> 0.0736 | Y6: =Rate_Shock_Model!E15 -> 267.05588 | Z6: =Rate_Shock_Model!G15 -> 993100.51 | AA6: =Rate_Shock_Model!B15 -> 0.01
Q7: 1976 | R7: =SUMIFS(Rate_Data!$B:$B,Rate_Data!$D:$D,Q7)/COUNTIFS(Rate_Data!$D:$D,Q7) -> 8.8658491 | S7: =Rate_Data!$H$2 -> 6.36 | T7: =Rate_Shock_Model!A16 -> Rate +1.50% | U7: =Rate_Shock_Model!D16 -> 2896.1141 | V7: =Rate_Shock_Model!F16 -> 642601.06 | W7: =Rate_Shock_Model!H16 -> 345290.27 | X7: =Rate_Shock_Model!C16 -> 0.0786 | Y7: =Rate_Shock_Model!E16 -> 404.5574 | Z7: =Rate_Shock_Model!G16 -> 1042601.1 | AA7: =Rate_Shock_Model!B16 -> 0.015
A8: ="Source: FRED · "&TEXT(MAX(Rate_Data!A:A),"MMM D, YYYY") -> Source: FRED · May 14, 2026 | D8: ="$"&TEXT(Assump_LoanAmt/1000,"#,##0")&"K loan · 30 yrs · "&TEXT(Assump_BaseRate,"0.00%") -> $400K loan · 30 yrs · 6.36% | G8: Base case · 30-year term | J8: At base rate · 30-yr term | M8: =TEXT(Assump_CurrRate,"0.00%")&" → "&TEXT(Assump_PropRate,"0.00%")&" · $"&TEXT(Assump_ClosingCosts/1000,"#,##0")&"K closing" -> 7.00% → 6.00% · $6K closing | Q8: 1977 | R8: =SUMIFS(Rate_Data!$B:$B,Rate_Data!$D:$D,Q8)/COUNTIFS(Rate_Data!$D:$D,Q8) -> 8.8451923 | S8: =Rate_Data!$H$2 -> 6.36
M9: =Refinance_Analysis!B22 -> Refinance Makes Sense | Q9: 1978 | R9: =SUMIFS(Rate_Data!$B:$B,Rate_Data!$D:$D,Q9)/COUNTIFS(Rate_Data!$D:$D,Q9) -> 9.6417308 | S9: =Rate_Data!$H$2 -> 6.36
Q10: 1979 | R10: =SUMIFS(Rate_Data!$B:$B,Rate_Data!$D:$D,Q10)/COUNTIFS(Rate_Data!$D:$D,Q10) -> 11.203654 | S10: =Rate_Data!$H$2 -> 6.36
Q11: 1980 | R11: =SUMIFS(Rate_Data!$B:$B,Rate_Data!$D:$D,Q11)/COUNTIFS(Rate_Data!$D:$D,Q11) -> 13.742115 | S11: =Rate_Data!$H$2 -> 6.36
Q12: 1981 | R12: =SUMIFS(Rate_Data!$B:$B,Rate_Data!$D:$D,Q12)/COUNTIFS(Rate_Data!$D:$D,Q12) -> 16.641509 | S12: =Rate_Data!$H$2 -> 6.36
Q13: 1982 | R13: =SUMIFS(Rate_Data!$B:$B,Rate_Data!$D:$D,Q13)/COUNTIFS(Rate_Data!$D:$D,Q13) -> 16.043654 | S13: =Rate_Data!$H$2 -> 6.36
Q14: 1983 | R14: =SUMIFS(Rate_Data!$B:$B,Rate_Data!$D:$D,Q14)/COUNTIFS(Rate_Data!$D:$D,Q14) -> 13.235385 | S14: =Rate_Data!$H$2 -> 6.36
Q15: 1984 | R15: =SUMIFS(Rate_Data!$B:$B,Rate_Data!$D:$D,Q15)/COUNTIFS(Rate_Data!$D:$D,Q15) -> 13.877692 | S15: =Rate_Data!$H$2 -> 6.36
Q16: 1985 | R16: =SUMIFS(Rate_Data!$B:$B,Rate_Data!$D:$D,Q16)/COUNTIFS(Rate_Data!$D:$D,Q16) -> 12.430192 | S16: =Rate_Data!$H$2 -> 6.36
Q17: 1986 | R17: =SUMIFS(Rate_Data!$B:$B,Rate_Data!$D:$D,Q17)/COUNTIFS(Rate_Data!$D:$D,Q17) -> 10.187308 | S17: =Rate_Data!$H$2 -> 6.36
Q18: 1987 | R18: =SUMIFS(Rate_Data!$B:$B,Rate_Data!$D:$D,Q18)/COUNTIFS(Rate_Data!$D:$D,Q18) -> 10.213396 | S18: =Rate_Data!$H$2 -> 6.36
Q19: 1988 | R19: =SUMIFS(Rate_Data!$B:$B,Rate_Data!$D:$D,Q19)/COUNTIFS(Rate_Data!$D:$D,Q19) -> 10.341731 | S19: =Rate_Data!$H$2 -> 6.36
Q20: 1989 | R20: =SUMIFS(Rate_Data!$B:$B,Rate_Data!$D:$D,Q20)/COUNTIFS(Rate_Data!$D:$D,Q20) -> 10.319423 | S20: =Rate_Data!$H$2 -> 6.36
Q21: 1990 | R21: =SUMIFS(Rate_Data!$B:$B,Rate_Data!$D:$D,Q21)/COUNTIFS(Rate_Data!$D:$D,Q21) -> 10.129423 | S21: =Rate_Data!$H$2 -> 6.36
... Q50: 2019 | R50: =SUMIFS(Rate_Data!$B:$B,Rate_Data!$D:$D,Q50)/COUNTIFS(Rate_Data!$D:$D,Q50) -> 3.9357692 | S50: =Rate_Data!$H$2 -> 6.36
A51: Refinance Break-Even Summary | Q51: 2020 | R51: =SUMIFS(Rate_Data!$B:$B,Rate_Data!$D:$D,Q51)/COUNTIFS(Rate_Data!$D:$D,Q51) -> 3.1116981 | S51: =Rate_Data!$H$2 -> 6.36
A52: Visualization Interpretation Guide | Q52: 2021 | R52: =SUMIFS(Rate_Data!$B:$B,Rate_Data!$D:$D,Q52)/COUNTIFS(Rate_Data!$D:$D,Q52) -> 2.9576923 | S52: =Rate_Data!$H$2 -> 6.36
A53: 1. Rate History | B53: Annual averages show the historical mortgage-rate environment; the flat reference line marks the current latest rate so viewers can compare today against past years. | Q53: 2022 | R53: =SUMIFS(Rate_Data!$B:$B,Rate_Data!$D:$D,Q53)/COUNTIFS(Rate_Data!$D:$D,Q53) -> 5.3440385 | S53: =Rate_Data!$H$2 -> 6.36
A54: 2. Payment Sensitivity | B54: Higher rates increase monthly principal-and-interest payments on the same $400K loan; lower rates reduce the payment burden. | Q54: 2023 | R54: =SUMIFS(Rate_Data!$B:$B,Rate_Data!$D:$D,Q54)/COUNTIFS(Rate_Data!$D:$D,Q54) -> 6.8067308 | S54: =Rate_Data!$H$2 -> 6.36
A55: 3. Lifetime Interest | B55: Rate changes compound over 360 months, so small rate differences can produce large changes in total interest paid. | Q55: 2024 | R55: =SUMIFS(Rate_Data!$B:$B,Rate_Data!$D:$D,Q55)/COUNTIFS(Rate_Data!$D:$D,Q55) -> 6.7211538 | S55: =Rate_Data!$H$2 -> 6.36
A56: 4. Affordability | B56: With a fixed $2,500 monthly budget, higher rates reduce the loan principal a buyer can afford; lower rates expand purchasing power. | Q56: 2025 | R56: =SUMIFS(Rate_Data!$B:$B,Rate_Data!$D:$D,Q56)/COUNTIFS(Rate_Data!$D:$D,Q56) -> 6.5950943 | S56: =Rate_Data!$H$2 -> 6.36
A57: 5. Refinance | B57: The default refinance case lowers the rate from 7.00% to 6.00%, producing positive monthly savings and a break-even period of about 24.7 months. | Q57: 2026 | R57: =SUMIFS(Rate_Data!$B:$B,Rate_Data!$D:$D,Q57)/COUNTIFS(Rate_Data!$D:$D,Q57) -> 6.1947368 | S57: =Rate_Data!$H$2 -> 6.36
